Workbook

Sheet Readme (or don't, whatever)

Sheet Team Data
A1: Pokemon | B1: Type1 | C1: Type2 | D1: Level | E1: HP | F1: ATK | G1: DEF | H1: SPA | I1: SPD | J1: SPE | K1: Move1 | L1: Move1Type | M1: Move1Power | N1: Move1Category | O1: Move1Accuracy | P1: Move2 | Q1: Move2Type | R1: Move2Power | S1: Move2Category | T1: Move2Accuracy | U1: Move3 | V1: Move3Type | W1: Move3Power | X1: Move3Category | Y1: Move3Accuracy | Z1: Move4 | AA1: Move4Type | AB1: Move4Power | AC1: Move4Category | AD1: Move4Accuracy | AE1: Ability | AF1: Held Item | AG1: EffectiveDEF | AH1: EffectiveSPD
A2: Chandelure | B2: Ghost | C2: Fire | D2: 58 | E2: 159 | F2: 93 | G2: 124 | H2: 213 | I2: 108 | J2: 119 | K2: Shadow Ball | L2: =IFERROR(_xlfn.XLOOKUP(TeamData[[#This Row],[Move1]],MoveData[Move],MoveData[Type]),"") -> Ghost | M2: =IFERROR(_xlfn.XLOOKUP(TeamData[[#This Row],[Move1]],MoveData[Move],MoveData[Power]),"") -> 80 | N2: =IFERROR(_xlfn.XLOOKUP(TeamData[[#This Row],[Move1]],MoveData[Move],MoveData[Category]),"") -> Special | O2: =IFERROR(_xlfn.XLOOKUP(TeamData[[#This Row],[Move1]],MoveData[Move],MoveData[Accuracy]),"") -> 100 | P2: Hex | Q2: =IFERROR(_xlfn.XLOOKUP(TeamData[[#This Row],[Move2]],MoveData[Move],MoveData[Type]),"") -> Ghost | R2: =IFERROR(_xlfn.XLOOKUP(TeamData[[#This Row],[Move2]],MoveData[Move],MoveData[Power]),"") -> 65 | S2: =IFERROR(_xlfn.XLOOKUP(TeamData[[#This Row],[Move2]],MoveData[Move],MoveData[Category]),"") -> Special | T2: =IFERROR(_xlfn.XLOOKUP(TeamData[[#This Row],[Move2]],MoveData[Move],MoveData[Accuracy]),"") -> 100 | U2: Will-O-Wisp | V2: =IFERROR(_xlfn.XLOOKUP(TeamData[[#This Row],[Move3]],MoveData[Move],MoveData[Type]),"") -> Fire | W2: =IFERROR(_xlfn.XLOOKUP(TeamData[[#This Row],[Move3]],MoveData[Move],MoveData[Power]),"") -> 0 | X2: =IFERROR(_xlfn.XLOOKUP(TeamData[[#This Row],[Move3]],MoveData[Move],MoveData[Category]),"") -> Status | Y2: =IFERROR(_xlfn.XLOOKUP(TeamData[[#This Row],[Move3]],MoveData[Move],MoveData[Accuracy]),"") -> 85 | Z2: Heat Wave | AA2: =IFERROR(_xlfn.XLOOKUP(TeamData[[#This Row],[Move4]],MoveData[Move],MoveData[Type]),"") -> Fire | AB2: =IFERROR(_xlfn.XLOOKUP(TeamData[[#This Row],[Move4]],MoveData[Move],MoveData[Power]),"") -> 95 | AC2: =IFERROR(_xlfn.XLOOKUP(TeamData[[#This Row],[Move4]],MoveData[Move],MoveData[Category]),"") -> Special | AD2: =IFERROR(_xlfn.XLOOKUP(TeamData[[#This Row],[Move4]],MoveData[Move],MoveData[Accuracy]),"") -> 90 | AE2: Flash Fire | AF2: Charcoal | AG2: =_xlfn.LET( _xlpm.item, TeamData[[#This Row],[Held Item]], _xlpm.effectType, _xlfn.XLOOKUP(_xlpm.item, Items[Item], Items[EffectType], "None"), _xlpm.statAffected, _xlfn.XLOOKUP(_xlpm.item, Items[Item], Items[StatAffected], "None"), _xlpm.multiplier, _xlfn.XLOOKUP(_xlpm.item, Items[Item], Items[Multiplier], 1), _xlpm.finalMult, IF(AND(_xlpm.effectType="StatMultiplier", OR(_xlpm.statAffected="DEF/SPD", _xlpm.statAffected="DEF")), _xlpm.multiplier, 1), TeamData[[#This Row],[DEF]] * _xlpm.finalMult ) -> 124 | AH2: =_xlfn.LET( _xlpm.item, TeamData[[#This Row],[Held Item]], _xlpm.effectType, _xlfn.XLOOKUP(_xlpm.item, Items[Item], Items[EffectType], "None"), _xlpm.statAffected, _xlfn.XLOOKUP(_xlpm.item, Items[Item], Items[StatAffected], "None"), _xlpm.multiplier, _xlfn.XLOOKUP(_xlpm.item, Items[Item], Items[Multiplier], 1), _xlpm.finalMult, IF(AND(_xlpm.effectType="StatMultiplier", OR(_xlpm.statAffected="DEF/SPD", _xlpm.statAffected="SPD")), _xlpm.multiplier, 1), TeamData[[#This Row],[SPD]] * _xlpm.finalMult ) -> 108
A3: Corviknight | B3: Flying | C3: Steel | D3: 57 | E3: 195 | F3: 129 | G3: 144 | H3: 71 | I3: 125 | J3: 104 | K3: Drill Peck | L3: =IFERROR(_xlfn.XLOOKUP(TeamData[[#This Row],[Move1]],MoveData[Move],MoveData[Type]),"") -> Flying | M3: =IFERROR(_xlfn.XLOOKUP(TeamData[[#This Row],[Move1]],MoveData[Move],MoveData[Power]),"") -> 80 | N3: =IFERROR(_xlfn.XLOOKUP(TeamData[[#This Row],[Move1]],MoveData[Move],MoveData[Category]),"") -> Physical | O3: =IFERROR(_xlfn.XLOOKUP(TeamData[[#This Row],[Move1]],MoveData[Move],MoveData[Accuracy]),"") -> 100 | P3: Iron Head | Q3: =IFERROR(_xlfn.XLOOKUP(TeamData[[#This Row],[Move2]],MoveData[Move],MoveData[Type]),"") -> Steel | R3: =IFERROR(_xlfn.XLOOKUP(TeamData[[#This Row],[Move2]],MoveData[Move],MoveData[Power]),"") -> 80 | S3: =IFERROR(_xlfn.XLOOKUP(TeamData[[#This Row],[Move2]],MoveData[Move],MoveData[Category]),"") -> Physical | T3: =IFERROR(_xlfn.XLOOKUP(TeamData[[#This Row],[Move2]],MoveData[Move],MoveData[Accuracy]),"") -> 100 | U3: Iron Defense | V3: =IFERROR(_xlfn.XLOOKUP(TeamData[[#This Row],[Move3]],MoveData[Move],MoveData[Type]),"") -> Steel | W3: =IFERROR(_xlfn.XLOOKUP(TeamData[[#This Row],[Move3]],MoveData[Move],MoveData[Power]),"") -> 0 | X3: =IFERROR(_xlfn.XLOOKUP(TeamData[[#This Row],[Move3]],MoveData[Move],MoveData[Category]),"") -> Status | Y3: =IFERROR(_xlfn.XLOOKUP(TeamData[[#This Row],[Move3]],MoveData[Move],MoveData[Accuracy]),"") -> 100 | Z3: Body Press | AA3: =IFERROR(_xlfn.XLOOKUP(TeamData[[#This Row],[Move4]],MoveData[Move],MoveData[Type]),"") -> Fighting | AB3: =IFERROR(_xlfn.XLOOKUP(TeamData[[#This Row],[Move4]],MoveData[Move],MoveData[Power]),"") -> 80 | AC3: =IFERROR(_xlfn.XLOOKUP(TeamData[[#This Row],[Move4]],MoveData[Move],MoveData[Category]),"") -> Physical | AD3: =IFERROR(_xlfn.XLOOKUP(TeamData[[#This Row],[Move4]],MoveData[Move],MoveData[Accuracy]),"") -> 100 | AE3: Unnerve | AF3: Metal Coat | AG3: =_xlfn.LET( _xlpm.item, TeamData[[#This Row],[Held Item]], _xlpm.effectType, _xlfn.XLOOKUP(_xlpm.item, Items[Item], Items[EffectType], "None"), _xlpm.statAffected, _xlfn.XLOOKUP(_xlpm.item, Items[Item], Items[StatAffected], "None"), _xlpm.multiplier, _xlfn.XLOOKUP(_xlpm.item, Items[Item], Items[Multiplier], 1), _xlpm.finalMult, IF(AND(_xlpm.effectType="StatMultiplier", OR(_xlpm.statAffected="DEF/SPD", _xlpm.statAffected="DEF")), _xlpm.multiplier, 1), TeamData[[#This Row],[DEF]] * _xlpm.finalMult ) -> 144 | AH3: =_xlfn.LET( _xlpm.item, TeamData[[#This Row],[Held Item]], _xlpm.effectType, _xlfn.XLOOKUP(_xlpm.item, Items[Item], Items[EffectType], "None"), _xlpm.statAffected, _xlfn.XLOOKUP(_xlpm.item, Items[Item], Items[StatAffected], "None"), _xlpm.multiplier, _xlfn.XLOOKUP(_xlpm.item, Items[Item], Items[Multiplier], 1), _xlpm.finalMult, IF(AND(_xlpm.effectType="StatMultiplier", OR(_xlpm.statAffected="DEF/SPD", _xlpm.statAffected="SPD")), _xlpm.multiplier, 1), TeamData[[#This Row],[SPD]] * _xlpm.finalMult ) -> 125
A4: Raichu | B4: Electric | D4: 57 | E4: 149 | F4: 139 | G4: 92 | H4: 130 | I4: 112 | J4: 136 | K4: Dig | L4: =IFERROR(_xlfn.XLOOKUP(TeamData[[#This Row],[Move1]],MoveData[Move],MoveData[Type]),"") -> Ground | M4: =IFERROR(_xlfn.XLOOKUP(TeamData[[#This Row],[Move1]],MoveData[Move],MoveData[Power]),"") -> 80 | N4: =IFERROR(_xlfn.XLOOKUP(TeamData[[#This Row],[Move1]],MoveData[Move],MoveData[Category]),"") -> Physical | O4: =IFERROR(_xlfn.XLOOKUP(TeamData[[#This Row],[Move1]],MoveData[Move],MoveData[Accuracy]),"") -> 100 | P4: Thunderbolt | Q4: =IFERROR(_xlfn.XLOOKUP(TeamData[[#This Row],[Move2]],MoveData[Move],MoveData[Type]),"") -> Electric | R4: =IFERROR(_xlfn.XLOOKUP(TeamData[[#This Row],[Move2]],MoveData[Move],MoveData[Power]),"") -> 90 | S4: =IFERROR(_xlfn.XLOOKUP(TeamData[[#This Row],[Move2]],MoveData[Move],MoveData[Category]),"") -> Special | T4: =IFERROR(_xlfn.XLOOKUP(TeamData[[#This Row],[Move2]],MoveData[Move],MoveData[Accuracy]),"") -> 100 | U4: Wild Charge | V4: =IFERROR(_xlfn.XLOOKUP(TeamData[[#This Row],[Move3]],MoveData[Move],MoveData[Type]),"") -> Electric | W4: =IFERROR(_xlfn.XLOOKUP(TeamData[[#This Row],[Move3]],MoveData[Move],MoveData[Power]),"") -> 90 | X4: =IFERROR(_xlfn.XLOOKUP(TeamData[[#This Row],[Move3]],MoveData[Move],MoveData[Category]),"") -> Physical | Y4: =IFERROR(_xlfn.XLOOKUP(TeamData[[#This Row],[Move3]],MoveData[Move],MoveData[Accuracy]),"") -> 100 | Z4: Surf | AA4: =IFERROR(_xlfn.XLOOKUP(TeamData[[#This Row],[Move4]],MoveData[Move],MoveData[Type]),"") -> Water | AB4: =IFERROR(_xlfn.XLOOKUP(TeamData[[#This Row],[Move4]],MoveData[Move],MoveData[Power]),"") -> 90 | AC4: =IFERROR(_xlfn.XLOOKUP(TeamData[[#This Row],[Move4]],MoveData[Move],MoveData[Category]),"") -> Special | AD4: =IFERROR(_xlfn.XLOOKUP(TeamData[[#This Row],[Move4]],MoveData[Move],MoveData[Accuracy]),"") -> 100 | AE4: Static | AF4: Expert Belt | AG4: =_xlfn.LET( _xlpm.item, TeamData[[#This Row],[Held Item]], _xlpm.effectType, _xlfn.XLOOKUP(_xlpm.item, Items[Item], Items[EffectType], "None"), _xlpm.statAffected, _xlfn.XLOOKUP(_xlpm.item, Items[Item], Items[StatAffected], "None"), _xlpm.multiplier, _xlfn.XLOOKUP(_xlpm.item, Items[Item], Items[Multiplier], 1), _xlpm.finalMult, IF(AND(_xlpm.effectType="StatMultiplier", OR(_xlpm.statAffected="DEF/SPD", _xlpm.statAffected="DEF")), _xlpm.multiplier, 1), TeamData[[#This Row],[DEF]] * _xlpm.finalMult ) -> 92 | AH4: =_xlfn.LET( _xlpm.item, TeamData[[#This Row],[Held Item]], _xlpm.effectType, _xlfn.XLOOKUP(_xlpm.item, Items[Item], Items[EffectType], "None"), _xlpm.statAffected, _xlfn.XLOOKUP(_xlpm.item, Items[Item], Items[StatAffected], "None"), _xlpm.multiplier, _xlfn.XLOOKUP(_xlpm.item, Items[Item], Items[Multiplier], 1), _xlpm.finalMult, IF(AND(_xlpm.effectType="StatMultiplier", OR(_xlpm.statAffected="DEF/SPD", _xlpm.statAffected="SPD")), _xlpm.multiplier, 1), TeamData[[#This Row],[SPD]] * _xlpm.finalMult ) -> 112
A5: Liepard | B5: Dark | D5: 57 | E5: 147 | F5: 137 | G5: 76 | H5: 141 | I5: 72 | J5: 128 | K5: Throat Chop | L5: =IFERROR(_xlfn.XLOOKUP(TeamData[[#This Row],[Move1]],MoveData[Move],MoveData[Type]),"") -> Dark | M5: =IFERROR(_xlfn.XLOOKUP(TeamData[[#This Row],[Move1]],MoveData[Move],MoveData[Power]),"") -> 80 | N5: =IFERROR(_xlfn.XLOOKUP(TeamData[[#This Row],[Move1]],MoveData[Move],MoveData[Category]),"") -> Physical | O5: =IFERROR(_xlfn.XLOOKUP(TeamData[[#This Row],[Move1]],MoveData[Move],MoveData[Accuracy]),"") -> 100 | P5: Dark Pulse | Q5: =IFERROR(_xlfn.XLOOKUP(TeamData[[#This Row],[Move2]],MoveData[Move],MoveData[Type]),"") -> Dark | R5: =IFERROR(_xlfn.XLOOKUP(TeamData[[#This Row],[Move2]],MoveData[Move],MoveData[Power]),"") -> 80 | S5: =IFERROR(_xlfn.XLOOKUP(TeamData[[#This Row],[Move2]],MoveData[Move],MoveData[Category]),"") -> Special | T5: =IFERROR(_xlfn.XLOOKUP(TeamData[[#This Row],[Move2]],MoveData[Move],MoveData[Accuracy]),"") -> 100 | U5: Assurance | V5: =IFERROR(_xlfn.XLOOKUP(TeamData[[#This Row],[Move3]],MoveData[Move],MoveData[Type]),"") -> Dark | W5: =IFERROR(_xlfn.XLOOKUP(TeamData[[#This Row],[Move3]],MoveData[Move],MoveData[Power]),"") -> 60 | X5: =IFERROR(_xlfn.XLOOKUP(TeamData[[#This Row],[Move3]],MoveData[Move],MoveData[Category]),"") -> Physical | Y5: =IFERROR(_xlfn.XLOOKUP(TeamData[[#This Row],[Move3]],MoveData[Move],MoveData[Accuracy]),"") -> 100 | Z5: Fake Out | AA5: =IFERROR(_xlfn.XLOOKUP(TeamData[[#This Row],[Move4]],MoveData[Move],MoveData[Type]),"") -> Normal | AB5: =IFERROR(_xlfn.XLOOKUP(TeamData[[#This Row],[Move4]],MoveData[Move],MoveData[Power]),"") -> 40 | AC5: =IFERROR(_xlfn.XLOOKUP(TeamData[[#This Row],[Move4]],MoveData[Move],MoveData[Category]),"") -> Physical | AD5: =IFERROR(_xlfn.XLOOKUP(TeamData[[#This Row],[Move4]],MoveData[Move],MoveData[Accuracy]),"") -> 100 | AE5: Unburden | AF5: Black Glasses | AG5: =_xlfn.LET( _xlpm.item, TeamData[[#This Row],[Held Item]], _xlpm.effectType, _xlfn.XLOOKUP(_xlpm.item, Items[Item], Items[EffectType], "None"), _xlpm.statAffected, _xlfn.XLOOKUP(_xlpm.item, Items[Item], Items[StatAffected], "None"), _xlpm.multiplier, _xlfn.XLOOKUP(_xlpm.item, Items[Item], Items[Multiplier], 1), _xlpm.finalMult, IF(AND(_xlpm.effectType="StatMultiplier", OR(_xlpm.statAffected="DEF/SPD", _xlpm.statAffected="DEF")), _xlpm.multiplier, 1), TeamData[[#This Row],[DEF]] * _xlpm.finalMult ) -> 76 | AH5: =_xlfn.LET( _xlpm.item, TeamData[[#This Row],[Held Item]], _xlpm.effectType, _xlfn.XLOOKUP(_xlpm.item, Items[Item], Items[EffectType], "None"), _xlpm.statAffected, _xlfn.XLOOKUP(_xlpm.item, Items[Item], Items[StatAffected], "None"), _xlpm.multiplier, _xlfn.XLOOKUP(_xlpm.item, Items[Item], Items[Multiplier], 1), _xlpm.finalMult, IF(AND(_xlpm.effectType="StatMultiplier", OR(_xlpm.statAffected="DEF/SPD", _xlpm.statAffected="SPD")), _xlpm.multiplier, 1), TeamData[[#This Row],[SPD]] * _xlpm.finalMult ) -> 72
A6: Roserade | B6: Grass | C6: Poison | D6: 57 | E6: 153 | F6: 121 | G6: 92 | H6: 149 | I6: 147 | J6: 132 | K6: Toxic | L6: =IFERROR(_xlfn.XLOOKUP(TeamData[[#This Row],[Move1]],MoveData[Move],MoveData[Type]),"") -> Poison | M6: =IFERROR(_xlfn.XLOOKUP(TeamData[[#This Row],[Move1]],MoveData[Move],MoveData[Power]),"") -> 0 | N6: =IFERROR(_xlfn.XLOOKUP(TeamData[[#This Row],[Move1]],MoveData[Move],MoveData[Category]),"") -> Status | O6: =IFERROR(_xlfn.XLOOKUP(TeamData[[#This Row],[Move1]],MoveData[Move],MoveData[Accuracy]),"") -> 90 | P6: Stun Spore | Q6: =IFERROR(_xlfn.XLOOKUP(TeamData[[#This Row],[Move2]],MoveData[Move],MoveData[Type]),"") -> Grass | R6: =IFERROR(_xlfn.XLOOKUP(TeamData[[#This Row],[Move2]],MoveData[Move],MoveData[Power]),"") -> 0 | S6: =IFERROR(_xlfn.XLOOKUP(TeamData[[#This Row],[Move2]],MoveData[Move],MoveData[Category]),"") -> Status | T6: =IFERROR(_xlfn.XLOOKUP(TeamData[[#This Row],[Move2]],MoveData[Move],MoveData[Accuracy]),"") -> 75 | U6: Giga Drain | V6: =IFERROR(_xlfn.XLOOKUP(TeamData[[#This Row],[Move3]],MoveData[Move],MoveData[Type]),"") -> Grass | W6: =IFERROR(_xlfn.XLOOKUP(TeamData[[#This Row],[Move3]],MoveData[Move],MoveData[Power]),"") -> 75 | X6: =IFERROR(_xlfn.XLOOKUP(TeamData[[#This Row],[Move3]],MoveData[Move],MoveData[Category]),"") -> Special | Y6: =IFERROR(_xlfn.XLOOKUP(TeamData[[#This Row],[Move3]],MoveData[Move],MoveData[Accuracy]),"") -> 100 | Z6: Energy Ball | AA6: =IFERROR(_xlfn.XLOOKUP(TeamData[[#This Row],[Move4]],MoveData[Move],MoveData[Type]),"") -> Grass | AB6: =IFERROR(_xlfn.XLOOKUP(TeamData[[#This Row],[Move4]],MoveData[Move],MoveData[Power]),"") -> 90 | AC6: =IFERROR(_xlfn.XLOOKUP(TeamData[[#This Row],[Move4]],MoveData[Move],MoveData[Category]),"") -> Special | AD6: =IFERROR(_xlfn.XLOOKUP(TeamData[[#This Row],[Move4]],MoveData[Move],MoveData[Accuracy]),"") -> 100 | AE6: Poison Point | AF6: Black Sludge | AG6: =_xlfn.LET( _xlpm.item, TeamData[[#This Row],[Held Item]], _xlpm.effectType, _xlfn.XLOOKUP(_xlpm.item, Items[Item], Items[EffectType], "None"), _xlpm.statAffected, _xlfn.XLOOKUP(_xlpm.item, Items[Item], Items[StatAffected], "None"), _xlpm.multiplier, _xlfn.XLOOKUP(_xlpm.item, Items[Item], Items[Multiplier], 1), _xlpm.finalMult, IF(AND(_xlpm.effectType="StatMultiplier", OR(_xlpm.statAffected="DEF/SPD", _xlpm.statAffected="DEF")), _xlpm.multiplier, 1), TeamData[[#This Row],[DEF]] * _xlpm.finalMult ) -> 92 | AH6: =_xlfn.LET( _xlpm.item, TeamData[[#This Row],[Held Item]], _xlpm.effectType, _xlfn.XLOOKUP(_xlpm.item, Items[Item], Items[EffectType], "None"), _xlpm.statAffected, _xlfn.XLOOKUP(_xlpm.item, Items[Item], Items[StatAffected], "None"), _xlpm.multiplier, _xlfn.XLOOKUP(_xlpm.item, Items[Item], Items[Multiplier], 1), _xlpm.finalMult, IF(AND(_xlpm.effectType="StatMultiplier", OR(_xlpm.statAffected="DEF/SPD", _xlpm.statAffected="SPD")), _xlpm.multiplier, 1), TeamData[[#This Row],[SPD]] * _xlpm.finalMult ) -> 147
A7: Sylveon | B7: Fairy | D7: 57 | E7: 198 | F7: 116 | G7: 102 | H7: 135 | I7: 173 | J7: 106 | K7: Play Rough | L7: =IFERROR(_xlfn.XLOOKUP(TeamData[[#This Row],[Move1]],MoveData[Move],MoveData[Type]),"") -> Fairy | M7: =IFERROR(_xlfn.XLOOKUP(TeamData[[#This Row],[Move1]],MoveData[Move],MoveData[Power]),"") -> 90 | N7: =IFERROR(_xlfn.XLOOKUP(TeamData[[#This Row],[Move1]],MoveData[Move],MoveData[Category]),"") -> Physical | O7: =IFERROR(_xlfn.XLOOKUP(TeamData[[#This Row],[Move1]],MoveData[Move],MoveData[Accuracy]),"") -> 90 | P7: Moonblast | Q7: =IFERROR(_xlfn.XLOOKUP(TeamData[[#This Row],[Move2]],MoveData[Move],MoveData[Type]),"") -> Fairy | R7: =IFERROR(_xlfn.XLOOKUP(TeamData[[#This Row],[Move2]],MoveData[Move],MoveData[Power]),"") -> 95 | S7: =IFERROR(_xlfn.XLOOKUP(TeamData[[#This Row],[Move2]],MoveData[Move],MoveData[Category]),"") -> Special | T7: =IFERROR(_xlfn.XLOOKUP(TeamData[[#This Row],[Move2]],MoveData[Move],MoveData[Accuracy]),"") -> 100 | U7: Draining Kiss | V7: =IFERROR(_xlfn.XLOOKUP(TeamData[[#This Row],[Move3]],MoveData[Move],MoveData[Type]),"") -> Fairy | W7: =IFERROR(_xlfn.XLOOKUP(TeamData[[#This Row],[Move3]],MoveData[Move],MoveData[Power]),"") -> 50 | X7: =IFERROR(_xlfn.XLOOKUP(TeamData[[#This Row],[Move3]],MoveData[Move],MoveData[Category]),"") -> Special | Y7: =IFERROR(_xlfn.XLOOKUP(TeamData[[#This Row],[Move3]],MoveData[Move],MoveData[Accuracy]),"") -> 100 | Z7: Psyshock | AA7: =IFERROR(_xlfn.XLOOKUP(TeamData[[#This Row],[Move4]],MoveData[Move],MoveData[Type]),"") -> Psychic | AB7: =IFERROR(_xlfn.XLOOKUP(TeamData[[#This Row],[Move4]],MoveData[Move],MoveData[Power]),"") -> 80 | AC7: =IFERROR(_xlfn.XLOOKUP(TeamData[[#This Row],[Move4]],MoveData[Move],MoveData[Category]),"") -> Special | AD7: =IFERROR(_xlfn.XLOOKUP(TeamData[[#This Row],[Move4]],MoveData[Move],MoveData[Accuracy]),"") -> 100 | AE7: Cute Charm | AF7: Pixie Plate | AG7: =_xlfn.LET( _xlpm.item, TeamData[[#This Row],[Held Item]], _xlpm.effectType, _xlfn.XLOOKUP(_xlpm.item, Items[Item], Items[EffectType], "None"), _xlpm.statAffected, _xlfn.XLOOKUP(_xlpm.item, Items[Item], Items[StatAffected], "None"), _xlpm.multiplier, _xlfn.XLOOKUP(_xlpm.item, Items[Item], Items[Multiplier], 1), _xlpm.finalMult, IF(AND(_xlpm.effectType="StatMultiplier", OR(_xlpm.statAffected="DEF/SPD", _xlpm.statAffected="DEF")), _xlpm.multiplier, 1), TeamData[[#This Row],[DEF]] * _xlpm.finalMult ) -> 102 | AH7: =_xlfn.LET( _xlpm.item, TeamData[[#This Row],[Held Item]], _xlpm.effectType, _xlfn.XLOOKUP(_xlpm.item, Items[Item], Items[EffectType], "None"), _xlpm.statAffected, _xlfn.XLOOKUP(_xlpm.item, Items[Item], Items[StatAffected], "None"), _xlpm.multiplier, _xlfn.XLOOKUP(_xlpm.item, Items[Item], Items[Multiplier], 1), _xlpm.finalMult, IF(AND(_xlpm.effectType="StatMultiplier", OR(_xlpm.statAffected="DEF/SPD", _xlpm.statAffected="SPD")), _xlpm.multiplier, 1), TeamData[[#This Row],[SPD]] * _xlpm.finalMult ) -> 173

Sheet Ability Rules
A1: Ability | B1: Effect | C1: TargetType | D1: Modifier | E1: Notes
A2: Levitate | B2: Immunity | C2: Ground | D2: 0 | E2: Immune to Ground moves
A3: Flash Fire | B3: Immunity | C3: Fire | D3: 0 | E3: Immune to Fire moves
A4: Water Absorb | B4: Immunity | C4: Water | D4: 0 | E4: Immune to Water moves
A5: Volt Absorb | B5: Immunity | C5: Electric | D5: 0 | E5: Immune to Electric moves
A6: Lightning Rod | B6: Immunity | C6: Electric | D6: 0 | E6: Immune to Electric moves
A7: Motor Drive | B7: Immunity | C7: Electric | D7: 0 | E7: Immune to Electric moves
A8: Storm Drain | B8: Immunity | C8: Water | D8: 0 | E8: Immune to Water moves
A9: Sap Sipper | B9: Immunity | C9: Grass | D9: 0 | E9: Immune to Grass moves
A10: Dry Skin | B10: Immunity | C10: Water | D10: 0 | E10: Immune to Water moves
A11: Thick Fat | B11: Reduction | C11: Fire | D11: 0.5 | E11: Fire damage x0.5
A12: Thick Fat | B12: Reduction | C12: Ice | D12: 0.5 | E12: Ice damage x0.5
A13: Heatproof | B13: Reduction | C13: Fire | D13: 0.5 | E13: Fire damage x0.5
... A31: Sturdy | B31: Tactical | C31: OHKO | D31: 0 | E31: May survive an otherwise lethal hit at full HP.

Sheet Movelist
A1: Move | B1: Power | C1: Type | D1: Category | E1: Accuracy | F1: Hits | G1: MakesContact | H1: Priority | I1: DamageMethod | J1: MechanicsNotes | K1: ActivationCondition | L1: StatusEffect | M1: ActivationPowerMultiplier | N1: AtkStageChange | O1: DefStageChange | P1: SpAStageChange | Q1: SpDStageChange | R1: SpeStageChange
A2: 10,000,000 Volt Thunderbolt | B2: 195 | C2: Electric | D2: Special | E2: 100 | F2: 1 | G2: FALSE | H2: 0 | I2: Standard | K2: Always | M2: 1 | N2: 0 | O2: 0 | P2: 0 | Q2: 0 | R2: 0
A3: Absorb | B3: 20 | C3: Grass | D3: Special | E3: 100 | F3: 1 | G3: FALSE | H3: 0 | I3: Standard | K3: Always | M3: 1 | N3: 0 | O3: 0 | P3: 0 | Q3: 0 | R3: 0
A4: Accelerock | B4: 40 | C4: Rock | D4: Physical | E4: 100 | F4: 1 | G4: TRUE | H4: 1 | I4: Standard | K4: Always | M4: 1 | N4: 0 | O4: 0 | P4: 0 | Q4: 0 | R4: 0
A5: Acid | B5: 40 | C5: Poison | D5: Special | E5: 100 | F5: 1 | G5: FALSE | H5: 0 | I5: Standard | K5: Always | M5: 1 | N5: 0 | O5: 0 | P5: 0 | Q5: 0 | R5: 0
A6: Acid Spray | B6: 40 | C6: Poison | D6: Special | E6: 100 | F6: 1 | G6: FALSE | H6: 0 | I6: Standard | K6: Always | M6: 1 | N6: 0 | O6: 0 | P6: 0 | Q6: 0 | R6: 0
A7: Acrobatics | B7: 55 | C7: Flying | D7: Physical | E7: 100 | F7: 1 | G7: TRUE | H7: 0 | I7: Variable | J7: Variable damage. | K7: Always | M7: 1 | N7: 0 | O7: 0 | P7: 0 | Q7: 0 | R7: 0
A8: Aerial Ace | B8: 60 | C8: Flying | D8: Physical | E8: 100 | F8: 1 | G8: TRUE | H8: 0 | I8: Standard | K8: Always | M8: 1 | N8: 0 | O8: 0 | P8: 0 | Q8: 0 | R8: 0
A9: Aeroblast | B9: 100 | C9: Flying | D9: Special | E9: 95 | F9: 1 | G9: FALSE | H9: 0 | I9: Standard | K9: Always | M9: 1 | N9: 0 | O9: 0 | P9: 0 | Q9: 0 | R9: 0
A10: Air Cutter | B10: 60 | C10: Flying | D10: Special | E10: 95 | F10: 1 | G10: FALSE | H10: 0 | I10: Standard | K10: Always | M10: 1 | N10: 0 | O10: 0 | P10: 0 | Q10: 0 | R10: 0
A11: Air Slash | B11: 75 | C11: Flying | D11: Special | E11: 95 | F11: 1 | G11: FALSE | H11: 0 | I11: Standard | K11: Always | M11: 1 | N11: 0 | O11: 0 | P11: 0 | Q11: 0 | R11: 0
A12: Anchor Shot | B12: 80 | C12: Steel | D12: Physical | E12: 100 | F12: 1 | G12: TRUE | H12: 0 | I12: Standard | K12: Always | M12: 1 | N12: 0 | O12: 0 | P12: 0 | Q12: 0 | R12: 0
A13: Ancient Power | B13: 60 | C13: Rock | D13: Special | E13: 100 | F13: 1 | G13: FALSE | H13: 0 | I13: Standard | K13: Always | M13: 1 | N13: 0 | O13: 0 | P13: 0 | Q13: 0 | R13: 0
A14: Apple Acid | B14: 80 | C14: Grass | D14: Special | E14: 100 | F14: 1 | G14: FALSE | H14: 0 | I14: Standard | K14: Always | M14: 1 | N14: 0 | O14: 0 | P14: 0 | Q14: 0 | R14: 0
A15: Aqua Jet | B15: 40 | C15: Water | D15: Physical | E15: 100 | F15: 1 | G15: TRUE | H15: 1 | I15: Standard | K15: Always | M15: 1 | N15: 0 | O15: 0 | P15: 0 | Q15: 0 | R15: 0
A16: Aqua Tail | B16: 90 | C16: Water | D16: Physical | E16: 90 | F16: 1 | G16: TRUE | H16: 0 | I16: Standard | K16: Always | M16: 1 | N16: 0 | O16: 0 | P16: 0 | Q16: 0 | R16: 0
A17: Arm Thrust | B17: 15 | C17: Fighting | D17: Physical | E17: 100 | F17: 1 | G17: TRUE | H17: 0 | I17: Standard | K17: Always | M17: 1 | N17: 0 | O17: 0 | P17: 0 | Q17: 0 | R17: 0
A18: Assurance | B18: 60 | C18: Dark | D18: Physical | E18: 100 | F18: 1 | G18: TRUE | H18: 0 | I18: Variable | J18: Variable damage. | K18: RequiresUserHit | M18: 1 | N18: 0 | O18: 0 | P18: 0 | Q18: 0 | R18: 0
A19: Astonish | B19: 30 | C19: Ghost | D19: Physical | E19: 100 | F19: 1 | G19: TRUE | H19: 0 | I19: Standard | K19: Always | M19: 1 | N19: 0 | O19: 0 | P19: 0 | Q19: 0 | R19: 0
A20: Astral Barrage | B20: 120 | C20: Ghost | D20: Special | E20: 100 | F20: 1 | G20: FALSE | H20: 0 | I20: Standard | K20: Always | M20: 1 | N20: 0 | O20: 0 | P20: 0 | Q20: 0 | R20: 0
A21: Attack Order | B21: 90 | C21: Bug | D21: Physical | E21: 100 | F21: 1 | G21: FALSE | H21: 0 | I21: Standard | K21: Always | M21: 1 | N21: 0 | O21: 0 | P21: 0 | Q21: 0 | R21: 0
A22: Aura Sphere | B22: 80 | C22: Fighting | D22: Special | E22: 100 | F22: 1 | G22: FALSE | H22: 0 | I22: Standard | K22: Always | M22: 1 | N22: 0 | O22: 0 | P22: 0 | Q22: 0 | R22: 0
A23: Aura Wheel | B23: 110 | C23: Electric | D23: Physical | E23: 100 | F23: 1 | G23: FALSE | H23: 0 | I23: Standard | K23: Always | M23: 1 | N23: 0 | O23: 0 | P23: 0 | Q23: 0 | R23: 0
A24: Aurora Beam | B24: 65 | C24: Ice | D24: Special | E24: 100 | F24: 1 | G24: FALSE | H24: 0 | I24: Standard | K24: Always | M24: 1 | N24: 0 | O24: 0 | P24: 0 | Q24: 0 | R24: 0
A25: Avalanche | B25: 60 | C25: Ice | D25: Physical | E25: 100 | F25: 1 | G25: TRUE | H25: -5 | I25: Variable | J25: Variable damage. | K25: RequiresUserHit | M25: 1 | N25: 0 | O25: 0 | P25: 0 | Q25: 0 | R25: 0
A26: Baddy Bad | B26: 80 | C26: Dark | D26: Special | E26: 95 | F26: 1 | G26: FALSE | H26: 0 | I26: Standard | K26: Always | M26: 1 | N26: 0 | O26: 0 | P26: 0 | Q26: 0 | R26: 0
A27: Barb Barrage | B27: 60 | C27: Poison | D27: Physical | E27: 100 | F27: 1 | G27: FALSE | H27: 0 | I27: Standard | K27: Always | M27: 1 | N27: 0 | O27: 0 | P27: 0 | Q27: 0 | R27: 0
A28: Barrage | B28: 15 | C28: Normal | D28: Physical | E28: 85 | F28: 1 | G28: FALSE | H28: 0 | I28: Standard | K28: Always | M28: 1 | N28: 0 | O28: 0 | P28: 0 | Q28: 0 | R28: 0
A29: Beak Blast | B29: 100 | C29: Flying | D29: Physical | E29: 100 | F29: 1 | G29: FALSE | H29: -2 | I29: Standard | K29: Always | M29: 1 | N29: 0 | O29: 0 | P29: 0 | Q29: 0 | R29: 0
A30: Beat Up | B30: 0 | C30: Dark | D30: Physical | E30: 100 | F30: 1 | G30: FALSE | H30: 0 | I30: Variable | J30: Variable damage. | K30: Always | M30: 1 | N30: 0 | O30: 0 | P30: 0 | Q30: 0 | R30: 0
A31: Behemoth Bash | B31: 100 | C31: Steel | D31: Physical | E31: 100 | F31: 1 | G31: FALSE | H31: 0 | I31: Standard | K31: Always | M31: 1 | N31: 0 | O31: 0 | P31: 0 | Q31: 0 | R31: 0
A32: Behemoth Blade | B32: 100 | C32: Steel | D32: Physical | E32: 100 | F32: 1 | G32: FALSE | H32: 0 | I32: Standard | K32: Always | M32: 1 | N32: 0 | O32: 0 | P32: 0 | Q32: 0 | R32: 0
A33: Belch | B33: 120 | C33: Poison | D33: Special | E33: 90 | F33: 1 | G33: FALSE | H33: 0 | I33: Standard | K33: Always | M33: 1 | N33: 0 | O33: 0 | P33: 0 | Q33: 0 | R33: 0
A34: Bide | B34: 0 | C34: Normal | D34: Physical | E34: 100 | F34: 1 | G34: TRUE | H34: 1 | I34: Fixed | J34: Fixed damage. | K34: RequiresUserHit | M34: 1 | N34: 0 | O34: 0 | P34: 0 | Q34: 0 | R34: 0
A35: Bind | B35: 15 | C35: Normal | D35: Physical | E35: 85 | F35: 1 | G35: TRUE | H35: 0 | I35: Standard | K35: Always | M35: 1 | N35: 0 | O35: 0 | P35: 0 | Q35: 0 | R35: 0
A36: Bite | B36: 60 | C36: Dark | D36: Physical | E36: 100 | F36: 1 | G36: TRUE | H36: 0 | I36: Standard | K36: Always | M36: 1 | N36: 0 | O36: 0 | P36: 0 | Q36: 0 | R36: 0
A37: Bitter Malice | B37: 75 | C37: Ghost | D37: Special | E37: 100 | F37: 1 | G37: FALSE | H37: 0 | I37: Standard | K37: Always | M37: 1 | N37: 0 | O37: 0 | P37: 0 | Q37: 0 | R37: 0
A38: Blast Burn | B38: 150 | C38: Fire | D38: Special | E38: 90 | F38: 1 | G38: FALSE | H38: 0 | I38: Standard | K38: Always | M38: 1 | N38: 0 | O38: 0 | P38: 0 | Q38: 0 | R38: 0
A39: Blaze Kick | B39: 85 | C39: Fire | D39: Physical | E39: 90 | F39: 1 | G39: TRUE | H39: 0 | I39: Standard | K39: Always | M39: 1 | N39: 0 | O39: 0 | P39: 0 | Q39: 0 | R39: 0
A40: Bleakwind Storm | B40: 100 | C40: Flying | D40: Special | E40: 80 | F40: 1 | G40: FALSE | H40: 0 | I40: Standard | K40: Always | M40: 1 | N40: 0 | O40: 0 | P40: 0 | Q40: 0 | R40: 0
...

Sheet Type Chart
A1: AttackType ↓ / DefendingType → | B1: Normal | C1: Fire | D1: Water | E1: Electric | F1: Grass | G1: Ice | H1: Fighting | I1: Poison | J1: Ground | K1: Flying | L1: Psychic | M1: Bug | N1: Rock | O1: Ghost | P1: Dragon | Q1: Dark | R1: Steel | S1: Fairy
A2: Normal | B2: 1 | C2: 1 | D2: 1 | E2: 1 | F2: 1 | G2: 1 | H2: 1 | I2: 1 | J2: 1 | K2: 1 | L2: 1 | M2: 1 | N2: 0.5 | O2: 0 | P2: 1 | Q2: 1 | R2: 0.5 | S2: 1
A3: Fire | B3: 1 | C3: 0.5 | D3: 0.5 | E3: 1 | F3: 2 | G3: 2 | H3: 1 | I3: 1 | J3: 1 | K3: 1 | L3: 1 | M3: 2 | N3: 0.5 | O3: 1 | P3: 0.5 | Q3: 1 | R3: 2 | S3: 1
A4: Water | B4: 1 | C4: 2 | D4: 0.5 | E4: 1 | F4: 0.5 | G4: 1 | H4: 1 | I4: 1 | J4: 2 | K4: 1 | L4: 1 | M4: 1 | N4: 2 | O4: 1 | P4: 0.5 | Q4: 1 | R4: 1 | S4: 1
A5: Electric | B5: 1 | C5: 1 | D5: 2 | E5: 0.5 | F5: 0.5 | G5: 1 | H5: 1 | I5: 1 | J5: 0 | K5: 2 | L5: 1 | M5: 1 | N5: 1 | O5: 1 | P5: 0.5 | Q5: 1 | R5: 1 | S5: 1
A6: Grass | B6: 1 | C6: 0.5 | D6: 2 | E6: 1 | F6: 0.5 | G6: 1 | H6: 1 | I6: 0.5 | J6: 2 | K6: 0.5 | L6: 1 | M6: 0.5 | N6: 2 | O6: 1 | P6: 0.5 | Q6: 1 | R6: 0.5 | S6: 1
A7: Ice | B7: 1 | C7: 0.5 | D7: 0.5 | E7: 1 | F7: 2 | G7: 0.5 | H7: 1 | I7: 1 | J7: 2 | K7: 2 | L7: 1 | M7: 1 | N7: 1 | O7: 1 | P7: 2 | Q7: 1 | R7: 0.5 | S7: 1
A8: Fighting | B8: 2 | C8: 1 | D8: 1 | E8: 1 | F8: 1 | G8: 2 | H8: 1 | I8: 0.5 | J8: 1 | K8: 0.5 | L8: 0.5 | M8: 0.5 | N8: 2 | O8: 0 | P8: 1 | Q8: 2 | R8: 2 | S8: 0.5
A9: Poison | B9: 1 | C9: 1 | D9: 1 | E9: 1 | F9: 2 | G9: 1 | H9: 1 | I9: 0.5 | J9: 0.5 | K9: 1 | L9: 1 | M9: 1 | N9: 0.5 | O9: 0.5 | P9: 1 | Q9: 1 | R9: 0 | S9: 2
A10: Ground | B10: 1 | C10: 2 | D10: 1 | E10: 2 | F10: 1 | G10: 1 | H10: 1 | I10: 2 | J10: 1 | K10: 0 | L10: 1 | M10: 0.5 | N10: 2 | O10: 1 | P10: 1 | Q10: 1 | R10: 2 | S10: 1
A11: Flying | B11: 1 | C11: 1 | D11: 1 | E11: 0.5 | F11: 2 | G11: 1 | H11: 2 | I11: 1 | J11: 1 | K11: 1 | L11: 1 | M11: 2 | N11: 0.5 | O11: 1 | P11: 1 | Q11: 1 | R11: 0.5 | S11: 1
A12: Psychic | B12: 1 | C12: 1 | D12: 1 | E12: 1 | F12: 1 | G12: 1 | H12: 2 | I12: 2 | J12: 1 | K12: 1 | L12: 0.5 | M12: 1 | N12: 1 | O12: 1 | P12: 1 | Q12: 0 | R12: 0.5 | S12: 1
A13: Bug | B13: 1 | C13: 0.5 | D13: 1 | E13: 1 | F13: 2 | G13: 1 | H13: 0.5 | I13: 0.5 | J13: 1 | K13: 0.5 | L13: 2 | M13: 1 | N13: 1 | O13: 0.5 | P13: 1 | Q13: 2 | R13: 0.5 | S13: 0.5
... A19: Fairy | B19: 1 | C19: 0.5 | D19: 1 | E19: 1 | F19: 1 | G19: 1 | H19: 2 | I19: 0.5 | J19: 1 | K19: 1 | L19: 1 | M19: 1 | N19: 1 | O19: 1 | P19: 2 | Q19: 2 | R19: 0.5 | S19: 1

Sheet Opponent
A1: Trainer | B1: Battle | C1: BattleOrder | D1: Slot | E1: Pokemon | F1: Type1 | G1: Type2 | H1: HP | I1: ATK | J1: DEF | K1: SPA | L1: SPD | M1: SPE | N1: Level | O1: Notes | P1: Move1 | Q1: Move1Type | R1: Move1Category | S1: Move1Power | T1: Move1Accuracy | U1: Move2 | V1: Move2Type | W1: Move2Category | X1: Move2Power | Y1: Move2Accuracy | Z1: Move3 | AA1: Move3Type | AB1: Move3Category | AC1: Move3Power | AD1: Move3Accuracy | AE1: Move4 | AF1: Move4Type | AG1: Move4Category | AH1: Move4Power | AI1: Move4Accuracy | AJ1: Ability | AK1: AbilityNotes
A2: Bea | B2: Gym 4 | C2: 1 | D2: 1 | E2: Hitmontop | F2: Fighting | H2: 50 | I2: 95 | J2: 95 | K2: 35 | L2: 110 | M2: 70 | N2: 34 | O2: Verified | P2: Triple Kick | Q2: =IFERROR(VLOOKUP(P2,MoveData[],3,FALSE),"") -> Fighting | R2: =IFERROR(VLOOKUP(P2,MoveData[],4,FALSE),"") -> Physical | S2: 10 | T2: 90 | U2: Counter | V2: =IFERROR(VLOOKUP(U2,MoveData[],3,FALSE),"") -> Fighting | W2: =IFERROR(VLOOKUP(U2,MoveData[],4,FALSE),"") -> Physical | X2: 0 | Y2: 100 | Z2: Revenge | AA2: =IFERROR(VLOOKUP(Z2,MoveData[],3,FALSE),"") -> Fighting | AB2: =IFERROR(VLOOKUP(Z2,MoveData[],4,FALSE),"") -> Physical | AC2: 60 | AD2: 100 | AE2: Quick Attack | AF2: =IFERROR(VLOOKUP(AE2,MoveData[],3,FALSE),"") -> Normal | AG2: =IFERROR(VLOOKUP(AE2,MoveData[],4,FALSE),"") -> Physical | AH2: 40 | AI2: 100 | AJ2: Intimidate | AK2: Verified - Trainer specific
A3: Bea | B3: Gym 4 | C3: 1 | D3: 2 | E3: Pangoro | F3: Fighting | G3: Dark | H3: 95 | I3: 124 | J3: 78 | K3: 69 | L3: 71 | M3: 58 | N3: 34 | O3: Verified | P3: Bullet Punch | Q3: =IFERROR(VLOOKUP(P3,MoveData[],3,FALSE),"") -> Steel | R3: =IFERROR(VLOOKUP(P3,MoveData[],4,FALSE),"") -> Physical | S3: 40 | T3: 100 | U3: Night Slash | V3: =IFERROR(VLOOKUP(U3,MoveData[],3,FALSE),"") -> Dark | W3: =IFERROR(VLOOKUP(U3,MoveData[],4,FALSE),"") -> Physical | X3: 70 | Y3: 100 | Z3: Circle Throw | AA3: =IFERROR(VLOOKUP(Z3,MoveData[],3,FALSE),"") -> Fighting | AB3: =IFERROR(VLOOKUP(Z3,MoveData[],4,FALSE),"") -> Physical | AC3: 60 | AD3: 90 | AE3: Work Up | AF3: =IFERROR(VLOOKUP(AE3,MoveData[],3,FALSE),"") -> Normal | AG3: =IFERROR(VLOOKUP(AE3,MoveData[],4,FALSE),"") -> Status | AH3: 0 | AI3: 100 | AJ3: Iron Fist | AK3: Verified - Trainer specific
A4: Bea | B4: Gym 4 | C4: 1 | D4: 3 | E4: Sirfetch'd | F4: Fighting | H4: 62 | I4: 135 | J4: 95 | K4: 68 | L4: 82 | M4: 65 | N4: 35 | O4: Verified | P4: Brutal Swing | Q4: =IFERROR(VLOOKUP(P4,MoveData[],3,FALSE),"") -> Dark | R4: =IFERROR(VLOOKUP(P4,MoveData[],4,FALSE),"") -> Physical | S4: 60 | T4: 100 | U4: Revenge | V4: =IFERROR(VLOOKUP(U4,MoveData[],3,FALSE),"") -> Fighting | W4: =IFERROR(VLOOKUP(U4,MoveData[],4,FALSE),"") -> Physical | X4: 60 | Y4: 100 | Z4: Detect | AA4: =IFERROR(VLOOKUP(Z4,MoveData[],3,FALSE),"") -> Fighting | AB4: =IFERROR(VLOOKUP(Z4,MoveData[],4,FALSE),"") -> Status | AC4: 0 | AD4: 100 | AE4: Swords Dance | AF4: =IFERROR(VLOOKUP(AE4,MoveData[],3,FALSE),"") -> Normal | AG4: =IFERROR(VLOOKUP(AE4,MoveData[],4,FALSE),"") -> Status | AH4: 0 | AI4: 100 | AJ4: Scrappy | AK4: Verified - Trainer specific
A5: Bea | B5: Gym 4 | C5: 1 | D5: 4 | E5: Machamp | F5: Fighting | H5: 90 | I5: 130 | J5: 80 | K5: 65 | L5: 85 | M5: 55 | N5: 36 | O5: Verified | P5: G-Max Chi Strike | Q5: Fighting | R5: Physical | S5: 110 | T5: 100 | U5: Max Darkness | V5: Dark | W5: Physical | X5: 120 | Y5: 100 | Z5: Max Strike | AA5: Normal | AB5: Physical | AC5: 130 | AD5: 100 | AE5: Max Guard | AF5: =IFERROR(VLOOKUP(AE5,MoveData[],3,FALSE),"") -> Normal | AG5: =IFERROR(VLOOKUP(AE5,MoveData[],4,FALSE),"") -> Status | AH5: 0 | AI5: 100 | AJ5: Guts | AK5: Verified - Trainer specific
A6: Gordie | B6: Gym 6 | C6: 1 | D6: 1 | E6: Barbaracle | F6: Rock | G6: Water | H6: 72 | I6: 105 | J6: 115 | K6: 54 | L6: 86 | M6: 68 | N6: 40 | O6: Verified | P6: Razor Shell | Q6: =IFERROR(VLOOKUP(P6,MoveData[],3,FALSE),"") -> Water | R6: =IFERROR(VLOOKUP(P6,MoveData[],4,FALSE),"") -> Physical | S6: 75 | T6: 95 | U6: Rock Tomb | V6: =IFERROR(VLOOKUP(U6,MoveData[],3,FALSE),"") -> Rock | W6: =IFERROR(VLOOKUP(U6,MoveData[],4,FALSE),"") -> Physical | X6: 60 | Y6: 95 | Z6: Shell Smash | AA6: =IFERROR(VLOOKUP(Z6,MoveData[],3,FALSE),"") -> Normal | AB6: =IFERROR(VLOOKUP(Z6,MoveData[],4,FALSE),"") -> Status | AC6: 0 | AD6: 100 | AF6: =IFERROR(VLOOKUP(AE6,MoveData[],3,FALSE),"") | AG6: =IFERROR(VLOOKUP(AE6,MoveData[],4,FALSE),"") | AH6: 0 | AI6: 100 | AJ6: Tough Claws | AK6: Verified - Trainer specific
A7: Gordie | B7: Gym 6 | C7: 1 | D7: 2 | E7: Shuckle | F7: Bug | G7: Rock | H7: 20 | I7: 10 | J7: 230 | K7: 10 | L7: 230 | M7: 5 | N7: 40 | O7: Verified | P7: Stone Edge | Q7: =IFERROR(VLOOKUP(P7,MoveData[],3,FALSE),"") -> Rock | R7: =IFERROR(VLOOKUP(P7,MoveData[],4,FALSE),"") -> Physical | S7: 100 | T7: 80 | U7: Struggle Bug | V7: =IFERROR(VLOOKUP(U7,MoveData[],3,FALSE),"") -> Bug | W7: =IFERROR(VLOOKUP(U7,MoveData[],4,FALSE),"") -> Special | X7: 50 | Y7: 100 | Z7: Rock Tomb | AA7: =IFERROR(VLOOKUP(Z7,MoveData[],3,FALSE),"") -> Rock | AB7: =IFERROR(VLOOKUP(Z7,MoveData[],4,FALSE),"") -> Physical | AC7: 60 | AD7: 95 | AE7: Power Split | AF7: =IFERROR(VLOOKUP(AE7,MoveData[],3,FALSE),"") -> Psychic | AG7: =IFERROR(VLOOKUP(AE7,MoveData[],4,FALSE),"") -> Status | AH7: 0 | AI7: 100 | AJ7: Sturdy | AK7: Species default
A8: Gordie | B8: Gym 6 | C8: 1 | D8: 3 | E8: Stonjourner | F8: Rock | H8: 100 | I8: 125 | J8: 135 | K8: 20 | L8: 20 | M8: 70 | N8: 41 | O8: Verified | P8: Rock Tomb | Q8: =IFERROR(VLOOKUP(P8,MoveData[],3,FALSE),"") -> Rock | R8: =IFERROR(VLOOKUP(P8,MoveData[],4,FALSE),"") -> Physical | S8: 60 | T8: 95 | U8: Body Slam | V8: =IFERROR(VLOOKUP(U8,MoveData[],3,FALSE),"") -> Normal | W8: =IFERROR(VLOOKUP(U8,MoveData[],4,FALSE),"") -> Physical | X8: 85 | Y8: 100 | Z8: Stealth Rock | AA8: =IFERROR(VLOOKUP(Z8,MoveData[],3,FALSE),"") -> Rock | AB8: =IFERROR(VLOOKUP(Z8,MoveData[],4,FALSE),"") -> Status | AC8: 0 | AD8: 100 | AE8: Wonder Room | AF8: =IFERROR(VLOOKUP(AE8,MoveData[],3,FALSE),"") -> Psychic | AG8: =IFERROR(VLOOKUP(AE8,MoveData[],4,FALSE),"") -> Status | AH8: 0 | AI8: 100 | AJ8: Power Spot | AK8: Species only ability
A9: Gordie | B9: Gym 6 | C9: 1 | D9: 4 | E9: Coalossal | F9: Rock | G9: Fire | H9: 110 | I9: 80 | J9: 120 | K9: 80 | L9: 90 | M9: 30 | N9: 42 | O9: Verified | P9: Max Flare | Q9: Fire | R9: Physical | S9: 130 | T9: 100 | U9: G-Max Volcalith | V9: Rock | W9: Physical | X9: 110 | Y9: 100 | Z9: Max Guard | AA9: =IFERROR(VLOOKUP(Z9,MoveData[],3,FALSE),"") -> Normal | AB9: =IFERROR(VLOOKUP(Z9,MoveData[],4,FALSE),"") -> Status | AC9: 0 | AD9: 100 | AE9: Max Guard | AF9: =IFERROR(VLOOKUP(AE9,MoveData[],3,FALSE),"") -> Normal | AG9: =IFERROR(VLOOKUP(AE9,MoveData[],4,FALSE),"") -> Status | AH9: 0 | AI9: 100 | AJ9: Steam Engine | AK9: Verified - Trainer specific
A10: Hop | B10: Postwick | C10: 1 | D10: 1 | E10: Wooloo | F10: Normal | H10: 42 | I10: 40 | J10: 55 | K10: 40 | L10: 45 | M10: 48 | N10: 3 | O10: Verified | P10: Tackle | Q10: =IFERROR(VLOOKUP(P10,MoveData[],3,FALSE),"") -> Normal | R10: =IFERROR(VLOOKUP(P10,MoveData[],4,FALSE),"") -> Physical | S10: 40 | T10: 100 | V10: =IFERROR(VLOOKUP(U10,MoveData[],3,FALSE),"") | W10: =IFERROR(VLOOKUP(U10,MoveData[],4,FALSE),"") | X10: 0 | Y10: 100 | AA10: =IFERROR(VLOOKUP(Z10,MoveData[],3,FALSE),"") | AB10: =IFERROR(VLOOKUP(Z10,MoveData[],4,FALSE),"") | AC10: 0 | AD10: 100 | AF10: =IFERROR(VLOOKUP(AE10,MoveData[],3,FALSE),"") | AG10: =IFERROR(VLOOKUP(AE10,MoveData[],4,FALSE),"") | AH10: 0 | AI10: 100 | AJ10: Fluffy | AK10: Species default
A11: Hop | B11: Postwick | C11: 1 | D11: 2 | E11: Grookey | F11: Grass | H11: 50 | I11: 65 | J11: 50 | K11: 40 | L11: 40 | M11: 65 | N11: 5 | O11: Verified | P11: Scratch | Q11: =IFERROR(VLOOKUP(P11,MoveData[],3,FALSE),"") -> Normal | R11: =IFERROR(VLOOKUP(P11,MoveData[],4,FALSE),"") -> Physical | S11: 40 | T11: 100 | U11: Growl | V11: =IFERROR(VLOOKUP(U11,MoveData[],3,FALSE),"") -> Normal | W11: =IFERROR(VLOOKUP(U11,MoveData[],4,FALSE),"") -> Status | X11: 0 | Y11: 100 | AA11: =IFERROR(VLOOKUP(Z11,MoveData[],3,FALSE),"") | AB11: =IFERROR(VLOOKUP(Z11,MoveData[],4,FALSE),"") | AC11: 0 | AD11: 100 | AF11: =IFERROR(VLOOKUP(AE11,MoveData[],3,FALSE),"") | AG11: =IFERROR(VLOOKUP(AE11,MoveData[],4,FALSE),"") | AH11: 0 | AI11: 100 | AJ11: Overgrow | AK11: Starter ability
A12: Kabu | B12: Gym 3 | C12: 1 | D12: 1 | E12: Ninetales | F12: Fire | H12: 73 | I12: 76 | J12: 75 | K12: 81 | L12: 100 | M12: 100 | N12: 25 | O12: Verified | P12: Fire Spin | Q12: =IFERROR(VLOOKUP(P12,MoveData[],3,FALSE),"") -> Fire | R12: =IFERROR(VLOOKUP(P12,MoveData[],4,FALSE),"") -> Special | S12: 35 | T12: 85 | U12: Ember | V12: =IFERROR(VLOOKUP(U12,MoveData[],3,FALSE),"") -> Fire | W12: =IFERROR(VLOOKUP(U12,MoveData[],4,FALSE),"") -> Special | X12: 40 | Y12: 100 | Z12: Quick Attack | AA12: =IFERROR(VLOOKUP(Z12,MoveData[],3,FALSE),"") -> Normal | AB12: =IFERROR(VLOOKUP(Z12,MoveData[],4,FALSE),"") -> Physical | AC12: 40 | AD12: 100 | AE12: Will-O-Wisp | AF12: =IFERROR(VLOOKUP(AE12,MoveData[],3,FALSE),"") -> Fire | AG12: =IFERROR(VLOOKUP(AE12,MoveData[],4,FALSE),"") -> Status | AH12: 0 | AI12: 85 | AJ12: Flash Fire | AK12: Verified - Trainer specific
A13: Kabu | B13: Gym 3 | C13: 1 | D13: 2 | E13: Arcanine | F13: Fire | H13: 90 | I13: 110 | J13: 80 | K13: 100 | L13: 80 | M13: 95 | N13: 25 | O13: Verified | P13: Flame Wheel | Q13: =IFERROR(VLOOKUP(P13,MoveData[],3,FALSE),"") -> Fire | R13: =IFERROR(VLOOKUP(P13,MoveData[],4,FALSE),"") -> Physical | S13: 60 | T13: 100 | U13: Bite | V13: =IFERROR(VLOOKUP(U13,MoveData[],3,FALSE),"") -> Dark | W13: =IFERROR(VLOOKUP(U13,MoveData[],4,FALSE),"") -> Physical | X13: 60 | Y13: 100 | Z13: Agility | AA13: =IFERROR(VLOOKUP(Z13,MoveData[],3,FALSE),"") -> Psychic | AB13: =IFERROR(VLOOKUP(Z13,MoveData[],4,FALSE),"") -> Status | AC13: 0 | AD13: 100 | AE13: Will-O-Wisp | AF13: =IFERROR(VLOOKUP(AE13,MoveData[],3,FALSE),"") -> Fire | AG13: =IFERROR(VLOOKUP(AE13,MoveData[],4,FALSE),"") -> Status | AH13: 0 | AI13: 85 | AJ13: Flash Fire | AK13: Verified - Trainer specific
A14: Kabu | B14: Gym 3 | C14: 1 | D14: 3 | E14: Centiskorch | F14: Fire | G14: Bug | H14: 100 | I14: 115 | J14: 65 | K14: 90 | L14: 90 | M14: 65 | N14: 27 | O14: Verified | P14: G-Max Centiferno | Q14: Fire | R14: Physical | S14: 110 | T14: 100 | U14: Max Flutterby | V14: Bug | W14: Physical | X14: 110 | Y14: 100 | Z14: Max Guard | AA14: =IFERROR(VLOOKUP(Z14,MoveData[],3,FALSE),"") -> Normal | AB14: =IFERROR(VLOOKUP(Z14,MoveData[],4,FALSE),"") -> Status | AC14: 0 | AD14: 100 | AE14: Max Guard | AF14: =IFERROR(VLOOKUP(AE14,MoveData[],3,FALSE),"") -> Normal | AG14: =IFERROR(VLOOKUP(AE14,MoveData[],4,FALSE),"") -> Status | AH14: 0 | AI14: 100 | AJ14: Flash Fire | AK14: Verified - Trainer specific
A15: Leon | B15: Wyndon Stadium (Scorbunny) | C15: 1 | D15: 1 | E15: Aegislash | F15: Steel | G15: Ghost | H15: 60 | I15: 50 | J15: 140 | K15: 50 | L15: 140 | M15: 60 | N15: 62 | O15: Verified | P15: Sacred Sword | Q15: =IFERROR(VLOOKUP(P15,MoveData[],3,FALSE),"") -> Fighting | R15: =IFERROR(VLOOKUP(P15,MoveData[],4,FALSE),"") -> Physical | S15: 90 | T15: 100 | U15: Shadow Ball | V15: =IFERROR(VLOOKUP(U15,MoveData[],3,FALSE),"") -> Ghost | W15: =IFERROR(VLOOKUP(U15,MoveData[],4,FALSE),"") -> Special | X15: 80 | Y15: 100 | Z15: Flash Cannon | AA15: =IFERROR(VLOOKUP(Z15,MoveData[],3,FALSE),"") -> Steel | AB15: =IFERROR(VLOOKUP(Z15,MoveData[],4,FALSE),"") -> Special | AC15: 80 | AD15: 100 | AE15: King's Shield | AF15: =IFERROR(VLOOKUP(AE15,MoveData[],3,FALSE),"") -> Steel | AG15: =IFERROR(VLOOKUP(AE15,MoveData[],4,FALSE),"") -> Status | AH15: 0 | AI15: 100 | AJ15: Stance Change | AK15: Species only ability
A16: Leon | B16: Wyndon Stadium (Scorbunny) | C16: 1 | D16: 2 | E16: Dragapult | F16: Dragon | G16: Ghost | H16: 88 | I16: 120 | J16: 75 | K16: 100 | L16: 75 | M16: 142 | N16: 62 | O16: Verified | P16: Shadow Ball | Q16: =IFERROR(VLOOKUP(P16,MoveData[],3,FALSE),"") -> Ghost | R16: =IFERROR(VLOOKUP(P16,MoveData[],4,FALSE),"") -> Special | S16: 80 | T16: 100 | U16: Flamethrower | V16: =IFERROR(VLOOKUP(U16,MoveData[],3,FALSE),"") -> Fire | W16: =IFERROR(VLOOKUP(U16,MoveData[],4,FALSE),"") -> Special | X16: 90 | Y16: 100 | Z16: Thunderbolt | AA16: =IFERROR(VLOOKUP(Z16,MoveData[],3,FALSE),"") -> Electric | AB16: =IFERROR(VLOOKUP(Z16,MoveData[],4,FALSE),"") -> Special | AC16: 90 | AD16: 100 | AE16: Dragon Breath | AF16: =IFERROR(VLOOKUP(AE16,MoveData[],3,FALSE),"") -> Dragon | AG16: =IFERROR(VLOOKUP(AE16,MoveData[],4,FALSE),"") -> Special | AH16: 60 | AI16: 100 | AJ16: Clear Body | AK16: Verified - Trainer specific
A17: Leon | B17: Wyndon Stadium (Scorbunny) | C17: 1 | D17: 3 | E17: Haxorus | F17: Dragon | H17: 76 | I17: 147 | J17: 90 | K17: 60 | L17: 70 | M17: 97 | N17: 63 | O17: Verified | P17: Poison Jab | Q17: =IFERROR(VLOOKUP(P17,MoveData[],3,FALSE),"") -> Poison | R17: =IFERROR(VLOOKUP(P17,MoveData[],4,FALSE),"") -> Physical | S17: 80 | T17: 100 | U17: Iron Tail | V17: =IFERROR(VLOOKUP(U17,MoveData[],3,FALSE),"") -> Steel | W17: =IFERROR(VLOOKUP(U17,MoveData[],4,FALSE),"") -> Physical | X17: 100 | Y17: 75 | Z17: Outrage | AA17: =IFERROR(VLOOKUP(Z17,MoveData[],3,FALSE),"") -> Dragon | AB17: =IFERROR(VLOOKUP(Z17,MoveData[],4,FALSE),"") -> Physical | AC17: 120 | AD17: 100 | AE17: Earthquake | AF17: =IFERROR(VLOOKUP(AE17,MoveData[],3,FALSE),"") -> Ground | AG17: =IFERROR(VLOOKUP(AE17,MoveData[],4,FALSE),"") -> Physical | AH17: 100 | AI17: 100 | AJ17: Mold Breaker | AK17: Verified - Trainer specific
A18: Leon | B18: Wyndon Stadium (Scorbunny) | C18: 1 | D18: 4 | E18: Mr. Rime | F18: Ice | G18: Psychic | H18: 80 | I18: 85 | J18: 75 | K18: 110 | L18: 100 | M18: 70 | N18: 64 | O18: Verified | P18: Psychic | Q18: =IFERROR(VLOOKUP(P18,MoveData[],3,FALSE),"") -> Psychic | R18: =IFERROR(VLOOKUP(P18,MoveData[],4,FALSE),"") -> Special | S18: 90 | T18: 100 | U18: Freeze-Dry | V18: =IFERROR(VLOOKUP(U18,MoveData[],3,FALSE),"") -> Ice | W18: =IFERROR(VLOOKUP(U18,MoveData[],4,FALSE),"") -> Special | X18: 70 | Y18: 100 | Z18: Thunderbolt | AA18: =IFERROR(VLOOKUP(Z18,MoveData[],3,FALSE),"") -> Electric | AB18: =IFERROR(VLOOKUP(Z18,MoveData[],4,FALSE),"") -> Special | AC18: 90 | AD18: 100 | AE18: Teeter Dance | AF18: =IFERROR(VLOOKUP(AE18,MoveData[],3,FALSE),"") -> Normal | AG18: =IFERROR(VLOOKUP(AE18,MoveData[],4,FALSE),"") -> Status | AH18: 0 | AI18: 100 | AJ18: Tangled Feet | AK18: Verified - Trainer specific
A19: Leon | B19: Wyndon Stadium (Scorbunny) | C19: 1 | D19: 5 | E19: Inteleon | F19: Water | H19: 70 | I19: 85 | J19: 65 | K19: 125 | L19: 65 | M19: 120 | N19: 64 | O19: Verified | P19: Snipe Shot | Q19: =IFERROR(VLOOKUP(P19,MoveData[],3,FALSE),"") -> Water | R19: =IFERROR(VLOOKUP(P19,MoveData[],4,FALSE),"") -> Special | S19: 80 | T19: 100 | U19: Dark Pulse | V19: =IFERROR(VLOOKUP(U19,MoveData[],3,FALSE),"") -> Dark | W19: =IFERROR(VLOOKUP(U19,MoveData[],4,FALSE),"") -> Special | X19: 80 | Y19: 100 | Z19: Mud Shot | AA19: =IFERROR(VLOOKUP(Z19,MoveData[],3,FALSE),"") -> Ground | AB19: =IFERROR(VLOOKUP(Z19,MoveData[],4,FALSE),"") -> Special | AC19: 55 | AD19: 95 | AE19: Tearful Look | AF19: =IFERROR(VLOOKUP(AE19,MoveData[],3,FALSE),"") -> Normal | AG19: =IFERROR(VLOOKUP(AE19,MoveData[],4,FALSE),"") -> Status | AH19: 0 | AI19: 100 | AJ19: Torrent | AK19: Starter ability
A20: Leon | B20: Wyndon Stadium (Scorbunny) | C20: 1 | D20: 6 | E20: Charizard | F20: Fire | G20: Flying | H20: 78 | I20: 84 | J20: 78 | K20: 109 | L20: 85 | M20: 100 | N20: 65 | O20: Verified | P20: G-Max Wildfire | Q20: Fire | R20: Special | S20: 140 | T20: 100 | U20: Max Airstream | V20: Flying | W20: Special | X20: 130 | Y20: 100 | Z20: Max Overgrowth | AA20: Grass | AB20: Special | AC20: 140 | AD20: 100 | AE20: Max Rockfall | AF20: Rock | AG20: Special | AH20: 110 | AI20: 100 | AJ20: Blaze | AK20: Starter ability
A21: Marnie | B21: Budew Drop Inn | C21: 1 | D21: 1 | E21: Croagunk | F21: Poison | G21: Fighting | H21: 48 | I21: 61 | J21: 40 | K21: 61 | L21: 40 | M21: 50 | N21: 24 | O21: Verified | P21: Poison Sting | Q21: =IFERROR(VLOOKUP(P21,MoveData[],3,FALSE),"") -> Poison | R21: =IFERROR(VLOOKUP(P21,MoveData[],4,FALSE),"") -> Physical | S21: 15 | T21: 100 | U21: Venoshock | V21: =IFERROR(VLOOKUP(U21,MoveData[],3,FALSE),"") -> Poison | W21: =IFERROR(VLOOKUP(U21,MoveData[],4,FALSE),"") -> Special | X21: 65 | Y21: 100 | Z21: Revenge | AA21: =IFERROR(VLOOKUP(Z21,MoveData[],3,FALSE),"") -> Fighting | AB21: =IFERROR(VLOOKUP(Z21,MoveData[],4,FALSE),"") -> Physical | AC21: 60 | AD21: 100 | AE21: Sucker Punch | AF21: =IFERROR(VLOOKUP(AE21,MoveData[],3,FALSE),"") -> Dark | AG21: =IFERROR(VLOOKUP(AE21,MoveData[],4,FALSE),"") -> Physical | AH21: 70 | AI21: 100 | AJ21: Dry Skin | AK21: Verified - Trainer specific
A22: Marnie | B22: Budew Drop Inn | C22: 1 | D22: 2 | E22: Scraggy | F22: Dark | G22: Fighting | H22: 50 | I22: 75 | J22: 70 | K22: 35 | L22: 70 | M22: 48 | N22: 24 | O22: Verified | P22: Beat Up | Q22: =IFERROR(VLOOKUP(P22,MoveData[],3,FALSE),"") -> Dark | R22: =IFERROR(VLOOKUP(P22,MoveData[],4,FALSE),"") -> Physical | S22: 0 | T22: 100 | U22: Headbutt | V22: =IFERROR(VLOOKUP(U22,MoveData[],3,FALSE),"") -> Normal | W22: =IFERROR(VLOOKUP(U22,MoveData[],4,FALSE),"") -> Physical | X22: 70 | Y22: 100 | Z22: Low Kick | AA22: =IFERROR(VLOOKUP(Z22,MoveData[],3,FALSE),"") -> Fighting | AB22: =IFERROR(VLOOKUP(Z22,MoveData[],4,FALSE),"") -> Physical | AC22: 0 | AD22: 100 | AF22: =IFERROR(VLOOKUP(AE22,MoveData[],3,FALSE),"") | AG22: =IFERROR(VLOOKUP(AE22,MoveData[],4,FALSE),"") | AH22: 0 | AI22: 100 | AJ22: Moxie | AK22: Verified - Trainer specific
A23: Marnie | B23: Budew Drop Inn | C23: 1 | D23: 3 | E23: Morpeko | F23: Electric | G23: Dark | H23: 58 | I23: 95 | J23: 58 | K23: 70 | L23: 58 | M23: 97 | N23: 26 | O23: Verified | P23: Quick Attack | Q23: =IFERROR(VLOOKUP(P23,MoveData[],3,FALSE),"") -> Normal | R23: =IFERROR(VLOOKUP(P23,MoveData[],4,FALSE),"") -> Physical | S23: 40 | T23: 100 | U23: Thunder Shock | V23: =IFERROR(VLOOKUP(U23,MoveData[],3,FALSE),"") -> Electric | W23: =IFERROR(VLOOKUP(U23,MoveData[],4,FALSE),"") -> Special | X23: 40 | Y23: 100 | Z23: Bite | AA23: =IFERROR(VLOOKUP(Z23,MoveData[],3,FALSE),"") -> Dark | AB23: =IFERROR(VLOOKUP(Z23,MoveData[],4,FALSE),"") -> Physical | AC23: 60 | AD23: 100 | AF23: =IFERROR(VLOOKUP(AE23,MoveData[],3,FALSE),"") | AG23: =IFERROR(VLOOKUP(AE23,MoveData[],4,FALSE),"") | AH23: 0 | AI23: 100 | AJ23: Hunger Switch | AK23: Species only ability
A24: Milo | B24: Gym 1 | C24: 1 | D24: 1 | E24: Gossifleur | F24: Grass | H24: 40 | I24: 40 | J24: 60 | K24: 40 | L24: 60 | M24: 10 | N24: 19 | O24: Verified | P24: Magical Leaf | Q24: =IFERROR(VLOOKUP(P24,MoveData[],3,FALSE),"") -> Grass | R24: =IFERROR(VLOOKUP(P24,MoveData[],4,FALSE),"") -> Special | S24: 60 | T24: 100 | U24: Round | V24: =IFERROR(VLOOKUP(U24,MoveData[],3,FALSE),"") -> Normal | W24: =IFERROR(VLOOKUP(U24,MoveData[],4,FALSE),"") -> Special | X24: 60 | Y24: 100 | Z24: Rapid Spin | AA24: =IFERROR(VLOOKUP(Z24,MoveData[],3,FALSE),"") -> Normal | AB24: =IFERROR(VLOOKUP(Z24,MoveData[],4,FALSE),"") -> Physical | AC24: 50 | AD24: 100 | AF24: =IFERROR(VLOOKUP(AE24,MoveData[],3,FALSE),"") | AG24: =IFERROR(VLOOKUP(AE24,MoveData[],4,FALSE),"") | AH24: 0 | AI24: 100 | AJ24: Cotton Down | AK24: Verified - Trainer specific
A25: Milo | B25: Gym 1 | C25: 1 | D25: 2 | E25: Eldegoss | F25: Grass | H25: 60 | I25: 50 | J25: 90 | K25: 80 | L25: 120 | M25: 60 | N25: 20 | O25: Verified | P25: Max Overgrowth | Q25: Grass | R25: Special | S25: 110 | T25: 100 | U25: Max Overgrowth | V25: Grass | W25: Physical | X25: 90 | Y25: 100 | Z25: Max Strike | AA25: Normal | AB25: Special | AC25: 110 | AD25: 100 | AF25: =IFERROR(VLOOKUP(AE25,MoveData[],3,FALSE),"") | AG25: =IFERROR(VLOOKUP(AE25,MoveData[],4,FALSE),"") | AH25: 0 | AI25: 100 | AJ25: Cotton Down | AK25: Verified - Trainer specific
A26: Nessa | B26: Gym 2 | C26: 1 | D26: 1 | E26: Goldeen | F26: Water | H26: 45 | I26: 67 | J26: 60 | K26: 35 | L26: 50 | M26: 63 | N26: 22 | O26: Verified | P26: Water Pulse | Q26: =IFERROR(VLOOKUP(P26,MoveData[],3,FALSE),"") -> Water | R26: =IFERROR(VLOOKUP(P26,MoveData[],4,FALSE),"") -> Special | S26: 60 | T26: 100 | U26: Whirlpool | V26: =IFERROR(VLOOKUP(U26,MoveData[],3,FALSE),"") -> Water | W26: =IFERROR(VLOOKUP(U26,MoveData[],4,FALSE),"") -> Special | X26: 35 | Y26: 85 | Z26: Horn Attack | AA26: =IFERROR(VLOOKUP(Z26,MoveData[],3,FALSE),"") -> Normal | AB26: =IFERROR(VLOOKUP(Z26,MoveData[],4,FALSE),"") -> Physical | AC26: 65 | AD26: 100 | AE26: Agility | AF26: =IFERROR(VLOOKUP(AE26,MoveData[],3,FALSE),"") -> Psychic | AG26: =IFERROR(VLOOKUP(AE26,MoveData[],4,FALSE),"") -> Status | AH26: 0 | AI26: 100 | AJ26: Swift Swim | AK26: Verified - Trainer specific
A27: Nessa | B27: Gym 2 | C27: 1 | D27: 2 | E27: Arrokuda | F27: Water | H27: 41 | I27: 63 | J27: 40 | K27: 40 | L27: 30 | M27: 66 | N27: 23 | O27: Verified | P27: Aqua Jet | Q27: =IFERROR(VLOOKUP(P27,MoveData[],3,FALSE),"") -> Water | R27: =IFERROR(VLOOKUP(P27,MoveData[],4,FALSE),"") -> Physical | S27: 40 | T27: 100 | U27: Bite | V27: =IFERROR(VLOOKUP(U27,MoveData[],3,FALSE),"") -> Dark | W27: =IFERROR(VLOOKUP(U27,MoveData[],4,FALSE),"") -> Physical | X27: 60 | Y27: 100 | Z27: Whirlpool | AA27: =IFERROR(VLOOKUP(Z27,MoveData[],3,FALSE),"") -> Water | AB27: =IFERROR(VLOOKUP(Z27,MoveData[],4,FALSE),"") -> Special | AC27: 35 | AD27: 85 | AE27: Fury Attack | AF27: =IFERROR(VLOOKUP(AE27,MoveData[],3,FALSE),"") -> Normal | AG27: =IFERROR(VLOOKUP(AE27,MoveData[],4,FALSE),"") -> Physical | AH27: 15 | AI27: 85 | AJ27: Swift Swim | AK27: Species default
A28: Nessa | B28: Gym 2 | C28: 1 | D28: 3 | E28: Drednaw | F28: Water | G28: Rock | H28: 90 | I28: 115 | J28: 90 | K28: 48 | L28: 68 | M28: 74 | N28: 24 | O28: Verified | P28: Max Geyser | Q28: Water | R28: Physical | S28: 130 | T28: 100 | U28: Max Geyser | V28: Water | W28: Special | X28: 90 | Y28: 100 | Z28: Max Darkness | AA28: Dark | AB28: Physical | AC28: 110 | AD28: 100 | AE28: Max Strike | AF28: Normal | AG28: Physical | AH28: 120 | AI28: 100 | AJ28: Swift Swim | AK28: Verified - Trainer specific
A29: Oleana | B29: Rose Tower | C29: 1 | D29: 1 | E29: Froslass | F29: Ice | G29: Ghost | H29: 70 | I29: 80 | J29: 70 | K29: 80 | L29: 70 | M29: 110 | N29: 50 | O29: Verified | P29: Hex | Q29: =IFERROR(VLOOKUP(P29,MoveData[],3,FALSE),"") -> Ghost | R29: =IFERROR(VLOOKUP(P29,MoveData[],4,FALSE),"") -> Special | S29: 65 | T29: 100 | U29: Icy Wind | V29: =IFERROR(VLOOKUP(U29,MoveData[],3,FALSE),"") -> Ice | W29: =IFERROR(VLOOKUP(U29,MoveData[],4,FALSE),"") -> Special | X29: 55 | Y29: 95 | Z29: Will-O-Wisp | AA29: =IFERROR(VLOOKUP(Z29,MoveData[],3,FALSE),"") -> Fire | AB29: =IFERROR(VLOOKUP(Z29,MoveData[],4,FALSE),"") -> Status | AC29: 0 | AD29: 85 | AE29: Double Team | AF29: =IFERROR(VLOOKUP(AE29,MoveData[],3,FALSE),"") -> Normal | AG29: =IFERROR(VLOOKUP(AE29,MoveData[],4,FALSE),"") -> Status | AH29: 0 | AI29: 100 | AJ29: Snow Cloak | AK29: Species default
A30: Oleana | B30: Rose Tower | C30: 1 | D30: 4 | E30: Tsareena | F30: Grass | H30: 72 | I30: 120 | J30: 98 | K30: 50 | L30: 98 | M30: 72 | N30: 50 | O30: Verified | P30: Trop Kick | Q30: =IFERROR(VLOOKUP(P30,MoveData[],3,FALSE),"") -> Grass | R30: =IFERROR(VLOOKUP(P30,MoveData[],4,FALSE),"") -> Physical | S30: 70 | T30: 100 | U30: Stomp | V30: =IFERROR(VLOOKUP(U30,MoveData[],3,FALSE),"") -> Normal | W30: =IFERROR(VLOOKUP(U30,MoveData[],4,FALSE),"") -> Physical | X30: 65 | Y30: 100 | Z30: Acrobatics | AA30: =IFERROR(VLOOKUP(Z30,MoveData[],3,FALSE),"") -> Flying | AB30: =IFERROR(VLOOKUP(Z30,MoveData[],4,FALSE),"") -> Physical | AC30: 55 | AD30: 100 | AE30: Attract | AF30: =IFERROR(VLOOKUP(AE30,MoveData[],3,FALSE),"") -> Normal | AG30: =IFERROR(VLOOKUP(AE30,MoveData[],4,FALSE),"") -> Status | AH30: 0 | AI30: 100 | AJ30: Queenly Majesty | AK30: Verified - Trainer specific
A31: Oleana | B31: Rose Tower | C31: 1 | D31: 3 | E31: Salazzle | F31: Poison | G31: Fire | H31: 68 | I31: 64 | J31: 60 | K31: 111 | L31: 60 | M31: 117 | N31: 50 | O31: Verified | P31: Venoshock | Q31: =IFERROR(VLOOKUP(P31,MoveData[],3,FALSE),"") -> Poison | R31: =IFERROR(VLOOKUP(P31,MoveData[],4,FALSE),"") -> Special | S31: 65 | T31: 100 | U31: Incinerate | V31: =IFERROR(VLOOKUP(U31,MoveData[],3,FALSE),"") -> Fire | W31: =IFERROR(VLOOKUP(U31,MoveData[],4,FALSE),"") -> Special | X31: 60 | Y31: 100 | Z31: Dragon Pulse | AA31: =IFERROR(VLOOKUP(Z31,MoveData[],3,FALSE),"") -> Dragon | AB31: =IFERROR(VLOOKUP(Z31,MoveData[],4,FALSE),"") -> Special | AC31: 85 | AD31: 100 | AE31: Poison Gas | AF31: =IFERROR(VLOOKUP(AE31,MoveData[],3,FALSE),"") -> Poison | AG31: =IFERROR(VLOOKUP(AE31,MoveData[],4,FALSE),"") -> Status | AH31: 0 | AI31: 90 | AJ31: Corrosion | AK31: Species default
A32: Oleana | B32: Rose Tower | C32: 1 | D32: 2 | E32: Milotic | F32: Water | H32: 95 | I32: 60 | J32: 79 | K32: 100 | L32: 125 | M32: 81 | N32: 51 | O32: Verified | P32: Surf | Q32: =IFERROR(VLOOKUP(P32,MoveData[],3,FALSE),"") -> Water | R32: =IFERROR(VLOOKUP(P32,MoveData[],4,FALSE),"") -> Special | S32: 90 | T32: 100 | U32: Safeguard | V32: =IFERROR(VLOOKUP(U32,MoveData[],3,FALSE),"") -> Normal | W32: =IFERROR(VLOOKUP(U32,MoveData[],4,FALSE),"") -> Status | X32: 0 | Y32: 100 | Z32: Recover | AA32: =IFERROR(VLOOKUP(Z32,MoveData[],3,FALSE),"") -> Normal | AB32: =IFERROR(VLOOKUP(Z32,MoveData[],4,FALSE),"") -> Status | AC32: 0 | AD32: 100 | AE32: Aqua Ring | AF32: =IFERROR(VLOOKUP(AE32,MoveData[],3,FALSE),"") -> Water | AG32: =IFERROR(VLOOKUP(AE32,MoveData[],4,FALSE),"") -> Status | AH32: 0 | AI32: 100 | AJ32: Competitive | AK32: Verified - Trainer specific
A33: Oleana | B33: Rose Tower | C33: 1 | D33: 5 | E33: Garbodor | F33: Poison | H33: 80 | I33: 95 | J33: 82 | K33: 60 | L33: 82 | M33: 75 | N33: 52 | O33: Verified | P33: G-Max Malodor | Q33: Poison | R33: Physical | S33: 140 | T33: 100 | U33: Max Quake | V33: Ground | W33: Physical | X33: 130 | Y33: 100 | Z33: Max Rockfall | AA33: Rock | AB33: Physical | AC33: 90 | AD33: 100 | AE33: Max Guard | AF33: =IFERROR(VLOOKUP(AE33,MoveData[],3,FALSE),"") -> Normal | AG33: =IFERROR(VLOOKUP(AE33,MoveData[],4,FALSE),"") -> Status | AH33: 0 | AI33: 100 | AJ33: Stench | AK33: Verified - Trainer specific
A34: Opal | B34: Gym 5 | C34: 1 | D34: 1 | E34: Weezing | F34: Poison | G34: Fairy | H34: 65 | I34: 90 | J34: 120 | K34: 85 | L34: 70 | M34: 60 | N34: 36 | O34: Verified | P34: Sludge | Q34: =IFERROR(VLOOKUP(P34,MoveData[],3,FALSE),"") -> Poison | R34: =IFERROR(VLOOKUP(P34,MoveData[],4,FALSE),"") -> Special | S34: 65 | T34: 100 | U34: Fairy Wind | V34: =IFERROR(VLOOKUP(U34,MoveData[],3,FALSE),"") -> Fairy | W34: =IFERROR(VLOOKUP(U34,MoveData[],4,FALSE),"") -> Special | X34: 40 | Y34: 100 | Z34: Tackle | AA34: =IFERROR(VLOOKUP(Z34,MoveData[],3,FALSE),"") -> Normal | AB34: =IFERROR(VLOOKUP(Z34,MoveData[],4,FALSE),"") -> Physical | AC34: 40 | AD34: 100 | AF34: =IFERROR(VLOOKUP(AE34,MoveData[],3,FALSE),"") | AG34: =IFERROR(VLOOKUP(AE34,MoveData[],4,FALSE),"") | AH34: 0 | AI34: 100 | AJ34: Levitate | AK34: Verified - Galarian Weezing
A35: Opal | B35: Gym 5 | C35: 1 | D35: 2 | E35: Mawile | F35: Steel | G35: Fairy | H35: 50 | I35: 85 | J35: 85 | K35: 55 | L35: 55 | M35: 50 | N35: 36 | O35: Verified | P35: Draining Kiss | Q35: =IFERROR(VLOOKUP(P35,MoveData[],3,FALSE),"") -> Fairy | R35: =IFERROR(VLOOKUP(P35,MoveData[],4,FALSE),"") -> Special | S35: 50 | T35: 100 | U35: Crunch | V35: =IFERROR(VLOOKUP(U35,MoveData[],3,FALSE),"") -> Dark | W35: =IFERROR(VLOOKUP(U35,MoveData[],4,FALSE),"") -> Physical | X35: 80 | Y35: 100 | Z35: Astonish | AA35: =IFERROR(VLOOKUP(Z35,MoveData[],3,FALSE),"") -> Ghost | AB35: =IFERROR(VLOOKUP(Z35,MoveData[],4,FALSE),"") -> Physical | AC35: 30 | AD35: 100 | AE35: Iron Defense | AF35: =IFERROR(VLOOKUP(AE35,MoveData[],3,FALSE),"") -> Steel | AG35: =IFERROR(VLOOKUP(AE35,MoveData[],4,FALSE),"") -> Status | AH35: 0 | AI35: 100 | AJ35: Intimidate | AK35: Verified - Trainer specific
A36: Opal | B36: Gym 5 | C36: 1 | D36: 3 | E36: Togekiss | F36: Fairy | G36: Flying | H36: 85 | I36: 50 | J36: 95 | K36: 120 | L36: 115 | M36: 80 | N36: 37 | O36: Verified | P36: Air Slash | Q36: =IFERROR(VLOOKUP(P36,MoveData[],3,FALSE),"") -> Flying | R36: =IFERROR(VLOOKUP(P36,MoveData[],4,FALSE),"") -> Special | S36: 75 | T36: 95 | U36: Draining Kiss | V36: =IFERROR(VLOOKUP(U36,MoveData[],3,FALSE),"") -> Fairy | W36: =IFERROR(VLOOKUP(U36,MoveData[],4,FALSE),"") -> Special | X36: 50 | Y36: 100 | Z36: Ancient Power | AA36: =IFERROR(VLOOKUP(Z36,MoveData[],3,FALSE),"") -> Rock | AB36: =IFERROR(VLOOKUP(Z36,MoveData[],4,FALSE),"") -> Special | AC36: 60 | AD36: 100 | AF36: =IFERROR(VLOOKUP(AE36,MoveData[],3,FALSE),"") | AG36: =IFERROR(VLOOKUP(AE36,MoveData[],4,FALSE),"") | AH36: 0 | AI36: 100 | AJ36: Serene Grace | AK36: Verified - Trainer specific
A37: Opal | B37: Gym 5 | C37: 1 | D37: 4 | E37: Alcremie | F37: Fairy | H37: 65 | I37: 60 | J37: 75 | K37: 110 | L37: 121 | M37: 64 | N37: 38 | O37: Verified | P37: G-Max Finale | Q37: Fairy | R37: Special | S37: 100 | T37: 100 | U37: Max Guard | V37: =IFERROR(VLOOKUP(U37,MoveData[],3,FALSE),"") -> Normal | W37: =IFERROR(VLOOKUP(U37,MoveData[],4,FALSE),"") -> Status | X37: 0 | Y37: 100 | Z37: Max Guard | AA37: =IFERROR(VLOOKUP(Z37,MoveData[],3,FALSE),"") -> Normal | AB37: =IFERROR(VLOOKUP(Z37,MoveData[],4,FALSE),"") -> Status | AC37: 0 | AD37: 100 | AF37: =IFERROR(VLOOKUP(AE37,MoveData[],3,FALSE),"") | AG37: =IFERROR(VLOOKUP(AE37,MoveData[],4,FALSE),"") | AH37: 0 | AI37: 100 | AJ37: Sweet Veil | AK37: Verified - Trainer specific
A38: Piers | B38: Gym 7 | C38: 1 | D38: 1 | E38: Scrafty | F38: Dark | G38: Fighting | H38: 65 | I38: 90 | J38: 115 | K38: 45 | L38: 115 | M38: 58 | N38: 44 | O38: Verified | P38: Fake Out | Q38: =IFERROR(VLOOKUP(P38,MoveData[],3,FALSE),"") -> Normal | R38: =IFERROR(VLOOKUP(P38,MoveData[],4,FALSE),"") -> Physical | S38: 40 | T38: 100 | U38: Brick Break | V38: =IFERROR(VLOOKUP(U38,MoveData[],3,FALSE),"") -> Fighting | W38: =IFERROR(VLOOKUP(U38,MoveData[],4,FALSE),"") -> Physical | X38: 75 | Y38: 100 | Z38: Payback | AA38: =IFERROR(VLOOKUP(Z38,MoveData[],3,FALSE),"") -> Dark | AB38: =IFERROR(VLOOKUP(Z38,MoveData[],4,FALSE),"") -> Physical | AC38: 50 | AD38: 100 | AE38: Sand Attack | AF38: =IFERROR(VLOOKUP(AE38,MoveData[],3,FALSE),"") -> Ground | AG38: =IFERROR(VLOOKUP(AE38,MoveData[],4,FALSE),"") -> Status | AH38: 0 | AI38: 100 | AJ38: Intimidate | AK38: Verified - Trainer specific
